[2025-05-23T22:41:30.918+0000] {taskinstance.py:1157} INFO - Dependencies all met for dep_context=non-requeueable deps ti=<TaskInstance: punctuality_etl_dag.load_to_postgresql manual__2025-05-23T22:41:27.498684+00:00 [queued]>
[2025-05-23T22:41:30.923+0000] {taskinstance.py:1157} INFO - Dependencies all met for dep_context=requeueable deps ti=<TaskInstance: punctuality_etl_dag.load_to_postgresql manual__2025-05-23T22:41:27.498684+00:00 [queued]>
[2025-05-23T22:41:30.924+0000] {taskinstance.py:1359} INFO - Starting attempt 1 of 1
[2025-05-23T22:41:30.998+0000] {taskinstance.py:1380} INFO - Executing <Task(PythonOperator): load_to_postgresql> on 2025-05-23 22:41:27.498684+00:00
[2025-05-23T22:41:31.001+0000] {standard_task_runner.py:57} INFO - Started process 949 to run task
[2025-05-23T22:41:31.003+0000] {standard_task_runner.py:84} INFO - Running: ['***', 'tasks', 'run', 'punctuality_etl_dag', 'load_to_postgresql', 'manual__2025-05-23T22:41:27.498684+00:00', '--job-id', '42', '--raw', '--subdir', 'DAGS_FOLDER/punctuality_etl_dag.py', '--cfg-path', '/tmp/tmpma1wb5dy']
[2025-05-23T22:41:31.006+0000] {standard_task_runner.py:85} INFO - Job 42: Subtask load_to_postgresql
[2025-05-23T22:41:31.016+0000] {logging_mixin.py:151} WARNING - /home/***/.local/lib/python3.8/site-packages/***/settings.py:195 DeprecationWarning: The sql_alchemy_conn option in [core] has been moved to the sql_alchemy_conn option in [database] - the old setting has been used, but please update your config.
[2025-05-23T22:41:31.038+0000] {task_command.py:415} INFO - Running <TaskInstance: punctuality_etl_dag.load_to_postgresql manual__2025-05-23T22:41:27.498684+00:00 [running]> on host 8ac5b706b4e9
[2025-05-23T22:41:31.088+0000] {taskinstance.py:1660} INFO - Exporting env vars: AIRFLOW_CTX_DAG_OWNER='***' AIRFLOW_CTX_DAG_ID='punctuality_etl_dag' AIRFLOW_CTX_TASK_ID='load_to_postgresql' AIRFLOW_CTX_EXECUTION_DATE='2025-05-23T22:41:27.498684+00:00' AIRFLOW_CTX_TRY_NUMBER='1' AIRFLOW_CTX_DAG_RUN_ID='manual__2025-05-23T22:41:27.498684+00:00'
[2025-05-23T22:41:31.089+0000] {taskinstance.py:1935} ERROR - Task failed with exception
Traceback (most recent call last):
  File "/home/airflow/.local/lib/python3.8/site-packages/airflow/operators/python.py", line 192, in execute
    return_value = self.execute_callable()
  File "/home/airflow/.local/lib/python3.8/site-packages/airflow/operators/python.py", line 209, in execute_callable
    return self.python_callable(*self.op_args, **self.op_kwargs)
  File "/opt/airflow/scripts/load_punctuality.py", line 7, in load_punctuality_to_postgres
    conn = psycopg2.connect(
  File "/home/airflow/.local/lib/python3.8/site-packages/psycopg2/__init__.py", line 122, in connect
    conn = _connect(dsn, connection_factory=connection_factory, **kwasync)
psycopg2.OperationalError: connection to server at "localhost" (::1), port 5432 failed: Connection refused
	Is the server running on that host and accepting TCP/IP connections?
connection to server at "localhost" (127.0.0.1), port 5432 failed: Connection refused
	Is the server running on that host and accepting TCP/IP connections?

[2025-05-23T22:41:31.096+0000] {taskinstance.py:1398} INFO - Marking task as FAILED. dag_id=punctuality_etl_dag, task_id=load_to_postgresql, execution_date=20250523T224127, start_date=20250523T224130, end_date=20250523T224131
[2025-05-23T22:41:31.104+0000] {standard_task_runner.py:104} ERROR - Failed to execute job 42 for task load_to_postgresql (connection to server at "localhost" (::1), port 5432 failed: Connection refused
	Is the server running on that host and accepting TCP/IP connections?
connection to server at "localhost" (127.0.0.1), port 5432 failed: Connection refused
	Is the server running on that host and accepting TCP/IP connections?
; 949)
[2025-05-23T22:41:31.147+0000] {local_task_job_runner.py:228} INFO - Task exited with return code 1
[2025-05-23T22:41:31.159+0000] {taskinstance.py:2776} INFO - 0 downstream tasks scheduled from follow-on schedule check
