[2025-05-24T00:21:39.188+0000] {taskinstance.py:1157} INFO - Dependencies all met for dep_context=non-requeueable deps ti=<TaskInstance: punctuality_etl_dag.load_to_postgresql scheduled__2025-05-23T00:00:00+00:00 [queued]>
[2025-05-24T00:21:39.193+0000] {taskinstance.py:1157} INFO - Dependencies all met for dep_context=requeueable deps ti=<TaskInstance: punctuality_etl_dag.load_to_postgresql scheduled__2025-05-23T00:00:00+00:00 [queued]>
[2025-05-24T00:21:39.193+0000] {taskinstance.py:1359} INFO - Starting attempt 1 of 1
[2025-05-24T00:21:39.271+0000] {taskinstance.py:1380} INFO - Executing <Task(PythonOperator): load_to_postgresql> on 2025-05-23 00:00:00+00:00
[2025-05-24T00:21:39.275+0000] {standard_task_runner.py:57} INFO - Started process 292 to run task
[2025-05-24T00:21:39.278+0000] {standard_task_runner.py:84} INFO - Running: ['airflow', 'tasks', 'run', 'punctuality_etl_dag', 'load_to_postgresql', 'scheduled__2025-05-23T00:00:00+00:00', '--job-id', '13', '--raw', '--subdir', 'DAGS_FOLDER/punctuality_etl_dag.py', '--cfg-path', '/tmp/tmpi_lbbeei']
[2025-05-24T00:21:39.280+0000] {standard_task_runner.py:85} INFO - Job 13: Subtask load_to_postgresql
[2025-05-24T00:21:39.310+0000] {task_command.py:415} INFO - Running <TaskInstance: punctuality_etl_dag.load_to_postgresql scheduled__2025-05-23T00:00:00+00:00 [running]> on host a5551f46ca35
[2025-05-24T00:21:39.357+0000] {taskinstance.py:1660} INFO - Exporting env vars: AIRFLOW_CTX_DAG_OWNER='airflow' AIRFLOW_CTX_DAG_ID='punctuality_etl_dag' AIRFLOW_CTX_TASK_ID='load_to_postgresql' AIRFLOW_CTX_EXECUTION_DATE='2025-05-23T00:00:00+00:00' AIRFLOW_CTX_TRY_NUMBER='1' AIRFLOW_CTX_DAG_RUN_ID='scheduled__2025-05-23T00:00:00+00:00'
[2025-05-24T00:21:39.361+0000] {taskinstance.py:1935} ERROR - Task failed with exception
Traceback (most recent call last):
  File "/home/airflow/.local/lib/python3.8/site-packages/airflow/operators/python.py", line 192, in execute
    return_value = self.execute_callable()
  File "/home/airflow/.local/lib/python3.8/site-packages/airflow/operators/python.py", line 209, in execute_callable
    return self.python_callable(*self.op_args, **self.op_kwargs)
  File "/opt/airflow/scripts/load_punctuality.py", line 23, in load_punctuality_to_postgres
    cursor.copy_from(f, 'punctuality', sep=',', columns=(
psycopg2.errors.UndefinedTable: relation "punctuality" does not exist

[2025-05-24T00:21:39.368+0000] {taskinstance.py:1398} INFO - Marking task as FAILED. dag_id=punctuality_etl_dag, task_id=load_to_postgresql, execution_date=20250523T000000, start_date=20250524T002139, end_date=20250524T002139
[2025-05-24T00:21:39.377+0000] {standard_task_runner.py:104} ERROR - Failed to execute job 13 for task load_to_postgresql (relation "punctuality" does not exist
; 292)
[2025-05-24T00:21:39.421+0000] {local_task_job_runner.py:228} INFO - Task exited with return code 1
[2025-05-24T00:21:39.434+0000] {taskinstance.py:2776} INFO - 0 downstream tasks scheduled from follow-on schedule check
