[2025-05-24T00:32:56.337+0000] {taskinstance.py:1157} INFO - Dependencies all met for dep_context=non-requeueable deps ti=<TaskInstance: punctuality_etl_dag.load_to_postgresql manual__2025-05-24T00:32:52.636603+00:00 [queued]>
[2025-05-24T00:32:56.341+0000] {taskinstance.py:1157} INFO - Dependencies all met for dep_context=requeueable deps ti=<TaskInstance: punctuality_etl_dag.load_to_postgresql manual__2025-05-24T00:32:52.636603+00:00 [queued]>
[2025-05-24T00:32:56.341+0000] {taskinstance.py:1359} INFO - Starting attempt 1 of 1
[2025-05-24T00:32:56.413+0000] {taskinstance.py:1380} INFO - Executing <Task(PythonOperator): load_to_postgresql> on 2025-05-24 00:32:52.636603+00:00
[2025-05-24T00:32:56.416+0000] {standard_task_runner.py:57} INFO - Started process 697 to run task
[2025-05-24T00:32:56.418+0000] {standard_task_runner.py:84} INFO - Running: ['airflow', 'tasks', 'run', 'punctuality_etl_dag', 'load_to_postgresql', 'manual__2025-05-24T00:32:52.636603+00:00', '--job-id', '16', '--raw', '--subdir', 'DAGS_FOLDER/punctuality_etl_dag.py', '--cfg-path', '/tmp/tmpmf26hug2']
[2025-05-24T00:32:56.419+0000] {standard_task_runner.py:85} INFO - Job 16: Subtask load_to_postgresql
[2025-05-24T00:32:56.448+0000] {task_command.py:415} INFO - Running <TaskInstance: punctuality_etl_dag.load_to_postgresql manual__2025-05-24T00:32:52.636603+00:00 [running]> on host a5551f46ca35
[2025-05-24T00:32:56.492+0000] {taskinstance.py:1660} INFO - Exporting env vars: AIRFLOW_CTX_DAG_OWNER='airflow' AIRFLOW_CTX_DAG_ID='punctuality_etl_dag' AIRFLOW_CTX_TASK_ID='load_to_postgresql' AIRFLOW_CTX_EXECUTION_DATE='2025-05-24T00:32:52.636603+00:00' AIRFLOW_CTX_TRY_NUMBER='1' AIRFLOW_CTX_DAG_RUN_ID='manual__2025-05-24T00:32:52.636603+00:00'
[2025-05-24T00:32:56.495+0000] {taskinstance.py:1935} ERROR - Task failed with exception
Traceback (most recent call last):
  File "/home/airflow/.local/lib/python3.8/site-packages/airflow/operators/python.py", line 192, in execute
    return_value = self.execute_callable()
  File "/home/airflow/.local/lib/python3.8/site-packages/airflow/operators/python.py", line 209, in execute_callable
    return self.python_callable(*self.op_args, **self.op_kwargs)
  File "/opt/airflow/scripts/load_punctuality.py", line 23, in load_punctuality_to_postgres
    cursor.copy_from(f, 'public.punctuality', sep=',', columns=(
psycopg2.errors.UndefinedTable: relation "public.punctuality" does not exist

[2025-05-24T00:32:56.502+0000] {taskinstance.py:1398} INFO - Marking task as FAILED. dag_id=punctuality_etl_dag, task_id=load_to_postgresql, execution_date=20250524T003252, start_date=20250524T003256, end_date=20250524T003256
[2025-05-24T00:32:56.508+0000] {standard_task_runner.py:104} ERROR - Failed to execute job 16 for task load_to_postgresql (relation "public.punctuality" does not exist
; 697)
[2025-05-24T00:32:56.517+0000] {local_task_job_runner.py:228} INFO - Task exited with return code 1
[2025-05-24T00:32:56.529+0000] {taskinstance.py:2776} INFO - 0 downstream tasks scheduled from follow-on schedule check
