[2025-05-23T22:29:37.476+0000] {taskinstance.py:1157} INFO - Dependencies all met for dep_context=non-requeueable deps ti=<TaskInstance: cancellations_etl_dag.load_to_postgresql manual__2025-05-23T22:29:34.541704+00:00 [queued]>
[2025-05-23T22:29:37.480+0000] {taskinstance.py:1157} INFO - Dependencies all met for dep_context=requeueable deps ti=<TaskInstance: cancellations_etl_dag.load_to_postgresql manual__2025-05-23T22:29:34.541704+00:00 [queued]>
[2025-05-23T22:29:37.480+0000] {taskinstance.py:1359} INFO - Starting attempt 1 of 1
[2025-05-23T22:29:37.547+0000] {taskinstance.py:1380} INFO - Executing <Task(PythonOperator): load_to_postgresql> on 2025-05-23 22:29:34.541704+00:00
[2025-05-23T22:29:37.549+0000] {standard_task_runner.py:57} INFO - Started process 481 to run task
[2025-05-23T22:29:37.552+0000] {standard_task_runner.py:84} INFO - Running: ['***', 'tasks', 'run', 'cancellations_etl_dag', 'load_to_postgresql', 'manual__2025-05-23T22:29:34.541704+00:00', '--job-id', '30', '--raw', '--subdir', 'DAGS_FOLDER/cancellations_etl_dag.py', '--cfg-path', '/tmp/tmpgi1rx_ui']
[2025-05-23T22:29:37.553+0000] {standard_task_runner.py:85} INFO - Job 30: Subtask load_to_postgresql
[2025-05-23T22:29:37.563+0000] {logging_mixin.py:151} WARNING - /home/***/.local/lib/python3.8/site-packages/***/settings.py:195 DeprecationWarning: The sql_alchemy_conn option in [core] has been moved to the sql_alchemy_conn option in [database] - the old setting has been used, but please update your config.
[2025-05-23T22:29:37.582+0000] {task_command.py:415} INFO - Running <TaskInstance: cancellations_etl_dag.load_to_postgresql manual__2025-05-23T22:29:34.541704+00:00 [running]> on host 8ac5b706b4e9
[2025-05-23T22:29:37.624+0000] {taskinstance.py:1660} INFO - Exporting env vars: AIRFLOW_CTX_DAG_OWNER='***' AIRFLOW_CTX_DAG_ID='cancellations_etl_dag' AIRFLOW_CTX_TASK_ID='load_to_postgresql' AIRFLOW_CTX_EXECUTION_DATE='2025-05-23T22:29:34.541704+00:00' AIRFLOW_CTX_TRY_NUMBER='1' AIRFLOW_CTX_DAG_RUN_ID='manual__2025-05-23T22:29:34.541704+00:00'
[2025-05-23T22:29:37.632+0000] {logging_mixin.py:151} INFO - Rows after cleaning: 1053
[2025-05-23T22:29:37.634+0000] {taskinstance.py:1935} ERROR - Task failed with exception
Traceback (most recent call last):
  File "/home/airflow/.local/lib/python3.8/site-packages/airflow/operators/python.py", line 192, in execute
    return_value = self.execute_callable()
  File "/home/airflow/.local/lib/python3.8/site-packages/airflow/operators/python.py", line 209, in execute_callable
    return self.python_callable(*self.op_args, **self.op_kwargs)
  File "/opt/airflow/scripts/load_to_db.py", line 20, in load_cancellations_to_postgres
    conn = psycopg2.connect(
  File "/home/airflow/.local/lib/python3.8/site-packages/psycopg2/__init__.py", line 122, in connect
    conn = _connect(dsn, connection_factory=connection_factory, **kwasync)
psycopg2.OperationalError: connection to server at "postgres" (172.18.0.2), port 5432 failed: FATAL:  password authentication failed for user "asulaaman"

[2025-05-23T22:29:37.641+0000] {taskinstance.py:1398} INFO - Marking task as FAILED. dag_id=cancellations_etl_dag, task_id=load_to_postgresql, execution_date=20250523T222934, start_date=20250523T222937, end_date=20250523T222937
[2025-05-23T22:29:37.659+0000] {standard_task_runner.py:104} ERROR - Failed to execute job 30 for task load_to_postgresql (connection to server at "postgres" (172.18.0.2), port 5432 failed: FATAL:  password authentication failed for user "asulaaman"
; 481)
[2025-05-23T22:29:37.691+0000] {local_task_job_runner.py:228} INFO - Task exited with return code 1
[2025-05-23T22:29:37.704+0000] {taskinstance.py:2776} INFO - 0 downstream tasks scheduled from follow-on schedule check
