[2025-05-23T20:49:30.869+0000] {taskinstance.py:1157} INFO - Dependencies all met for dep_context=non-requeueable deps ti=<TaskInstance: cancellations_etl_dag.transform_data scheduled__2025-05-22T00:00:00+00:00 [queued]>
[2025-05-23T20:49:30.876+0000] {taskinstance.py:1157} INFO - Dependencies all met for dep_context=requeueable deps ti=<TaskInstance: cancellations_etl_dag.transform_data scheduled__2025-05-22T00:00:00+00:00 [queued]>
[2025-05-23T20:49:30.877+0000] {taskinstance.py:1359} INFO - Starting attempt 1 of 1
[2025-05-23T20:49:30.884+0000] {taskinstance.py:1380} INFO - Executing <Task(PythonOperator): transform_data> on 2025-05-22 00:00:00+00:00
[2025-05-23T20:49:30.888+0000] {standard_task_runner.py:57} INFO - Started process 426 to run task
[2025-05-23T20:49:30.894+0000] {standard_task_runner.py:84} INFO - Running: ['***', 'tasks', 'run', 'cancellations_etl_dag', 'transform_data', 'scheduled__2025-05-22T00:00:00+00:00', '--job-id', '8', '--raw', '--subdir', 'DAGS_FOLDER/cancellations_etl_dag.py', '--cfg-path', '/tmp/tmp_hm5uqjs']
[2025-05-23T20:49:30.898+0000] {standard_task_runner.py:85} INFO - Job 8: Subtask transform_data
[2025-05-23T20:49:30.923+0000] {logging_mixin.py:151} WARNING - /home/***/.local/lib/python3.8/site-packages/***/settings.py:195 DeprecationWarning: The sql_alchemy_conn option in [core] has been moved to the sql_alchemy_conn option in [database] - the old setting has been used, but please update your config.
[2025-05-23T20:49:30.961+0000] {task_command.py:415} INFO - Running <TaskInstance: cancellations_etl_dag.transform_data scheduled__2025-05-22T00:00:00+00:00 [running]> on host 9541251e9700
[2025-05-23T20:49:31.030+0000] {taskinstance.py:1660} INFO - Exporting env vars: AIRFLOW_CTX_DAG_OWNER='***' AIRFLOW_CTX_DAG_ID='cancellations_etl_dag' AIRFLOW_CTX_TASK_ID='transform_data' AIRFLOW_CTX_EXECUTION_DATE='2025-05-22T00:00:00+00:00' AIRFLOW_CTX_TRY_NUMBER='1' AIRFLOW_CTX_DAG_RUN_ID='scheduled__2025-05-22T00:00:00+00:00'
[2025-05-23T20:49:31.033+0000] {taskinstance.py:1935} ERROR - Task failed with exception
Traceback (most recent call last):
  File "/home/airflow/.local/lib/python3.8/site-packages/airflow/operators/python.py", line 192, in execute
    return_value = self.execute_callable()
  File "/home/airflow/.local/lib/python3.8/site-packages/airflow/operators/python.py", line 209, in execute_callable
    return self.python_callable(*self.op_args, **self.op_kwargs)
  File "/opt/airflow/scripts/transform_data.py", line 81, in clean_cancellation_data
    df = pd.read_csv(file_path, skiprows=4)
  File "/home/airflow/.local/lib/python3.8/site-packages/pandas/io/parsers/readers.py", line 912, in read_csv
    return _read(filepath_or_buffer, kwds)
  File "/home/airflow/.local/lib/python3.8/site-packages/pandas/io/parsers/readers.py", line 577, in _read
    parser = TextFileReader(filepath_or_buffer, **kwds)
  File "/home/airflow/.local/lib/python3.8/site-packages/pandas/io/parsers/readers.py", line 1407, in __init__
    self._engine = self._make_engine(f, self.engine)
  File "/home/airflow/.local/lib/python3.8/site-packages/pandas/io/parsers/readers.py", line 1661, in _make_engine
    self.handles = get_handle(
  File "/home/airflow/.local/lib/python3.8/site-packages/pandas/io/common.py", line 859, in get_handle
    handle = open(
FileNotFoundError: [Errno 2] No such file or directory: 'data/raw/cancellations.csv'
[2025-05-23T20:49:31.044+0000] {taskinstance.py:1398} INFO - Marking task as FAILED. dag_id=cancellations_etl_dag, task_id=transform_data, execution_date=20250522T000000, start_date=20250523T204930, end_date=20250523T204931
[2025-05-23T20:49:31.055+0000] {standard_task_runner.py:104} ERROR - Failed to execute job 8 for task transform_data ([Errno 2] No such file or directory: 'data/raw/cancellations.csv'; 426)
[2025-05-23T20:49:31.072+0000] {local_task_job_runner.py:228} INFO - Task exited with return code 1
[2025-05-23T20:49:31.093+0000] {taskinstance.py:2776} INFO - 0 downstream tasks scheduled from follow-on schedule check
