[2025-05-23T22:10:24.164+0000] {taskinstance.py:1157} INFO - Dependencies all met for dep_context=non-requeueable deps ti=<TaskInstance: train_delays_dag.load_to_db manual__2025-05-23T22:10:21.477300+00:00 [queued]>
[2025-05-23T22:10:24.168+0000] {taskinstance.py:1157} INFO - Dependencies all met for dep_context=requeueable deps ti=<TaskInstance: train_delays_dag.load_to_db manual__2025-05-23T22:10:21.477300+00:00 [queued]>
[2025-05-23T22:10:24.168+0000] {taskinstance.py:1359} INFO - Starting attempt 1 of 1
[2025-05-23T22:10:24.173+0000] {taskinstance.py:1380} INFO - Executing <Task(PythonOperator): load_to_db> on 2025-05-23 22:10:21.477300+00:00
[2025-05-23T22:10:24.176+0000] {standard_task_runner.py:57} INFO - Started process 247 to run task
[2025-05-23T22:10:24.178+0000] {standard_task_runner.py:84} INFO - Running: ['***', 'tasks', 'run', 'train_delays_dag', 'load_to_db', 'manual__2025-05-23T22:10:21.477300+00:00', '--job-id', '23', '--raw', '--subdir', 'DAGS_FOLDER/train_delays_dag.py', '--cfg-path', '/tmp/tmpcybwexrm']
[2025-05-23T22:10:24.179+0000] {standard_task_runner.py:85} INFO - Job 23: Subtask load_to_db
[2025-05-23T22:10:24.188+0000] {logging_mixin.py:151} WARNING - /home/***/.local/lib/python3.8/site-packages/***/settings.py:195 DeprecationWarning: The sql_alchemy_conn option in [core] has been moved to the sql_alchemy_conn option in [database] - the old setting has been used, but please update your config.
[2025-05-23T22:10:24.208+0000] {task_command.py:415} INFO - Running <TaskInstance: train_delays_dag.load_to_db manual__2025-05-23T22:10:21.477300+00:00 [running]> on host b5b9d485c58a
[2025-05-23T22:10:24.352+0000] {taskinstance.py:1660} INFO - Exporting env vars: AIRFLOW_CTX_DAG_OWNER='***' AIRFLOW_CTX_DAG_ID='train_delays_dag' AIRFLOW_CTX_TASK_ID='load_to_db' AIRFLOW_CTX_EXECUTION_DATE='2025-05-23T22:10:21.477300+00:00' AIRFLOW_CTX_TRY_NUMBER='1' AIRFLOW_CTX_DAG_RUN_ID='manual__2025-05-23T22:10:21.477300+00:00'
[2025-05-23T22:10:24.353+0000] {logging_mixin.py:151} INFO - Loading data to PostgreSQL...
[2025-05-23T22:10:24.353+0000] {taskinstance.py:1935} ERROR - Task failed with exception
Traceback (most recent call last):
  File "/home/airflow/.local/lib/python3.8/site-packages/airflow/operators/python.py", line 192, in execute
    return_value = self.execute_callable()
  File "/home/airflow/.local/lib/python3.8/site-packages/airflow/operators/python.py", line 209, in execute_callable
    return self.python_callable(*self.op_args, **self.op_kwargs)
  File "/opt/airflow/scripts/load_train_delays_to_db.py", line 8, in load_train_delays_to_postgres
    conn = psycopg2.connect(
  File "/home/airflow/.local/lib/python3.8/site-packages/psycopg2/__init__.py", line 122, in connect
    conn = _connect(dsn, connection_factory=connection_factory, **kwasync)
psycopg2.OperationalError: connection to server at "localhost" (::1), port 5432 failed: Connection refused
	Is the server running on that host and accepting TCP/IP connections?
connection to server at "localhost" (127.0.0.1), port 5432 failed: Connection refused
	Is the server running on that host and accepting TCP/IP connections?

[2025-05-23T22:10:24.359+0000] {taskinstance.py:1398} INFO - Marking task as FAILED. dag_id=train_delays_dag, task_id=load_to_db, execution_date=20250523T221021, start_date=20250523T221024, end_date=20250523T221024
[2025-05-23T22:10:24.365+0000] {standard_task_runner.py:104} ERROR - Failed to execute job 23 for task load_to_db (connection to server at "localhost" (::1), port 5432 failed: Connection refused
	Is the server running on that host and accepting TCP/IP connections?
connection to server at "localhost" (127.0.0.1), port 5432 failed: Connection refused
	Is the server running on that host and accepting TCP/IP connections?
; 247)
[2025-05-23T22:10:24.369+0000] {local_task_job_runner.py:228} INFO - Task exited with return code 1
[2025-05-23T22:10:24.381+0000] {taskinstance.py:2776} INFO - 0 downstream tasks scheduled from follow-on schedule check
